Workbook

Sheet MACRO EXCEL
A1: ID | B1: REVISION | C1: FECHA.REVISION | D1: TIEMPO.ENTRE.REVISIONES | E1: NOMBRE | F1: PACIENTE | G1: FECHA.NACIMIENTO | H1: EDAD | I1: INTERVALO.EDAD | J1: SEXO | K1: OJO | L1: MANO.DOMINANTE | M1: OJO.DOMINANTE | N1: DOMINANCIA.OJO.MANO | O1: MANO DOMINANTE valor | P1: OJO | Q1: SEXO nº | R1: OJO DOMINANTE valor | S1: DOM VALOR | T1: Nº rango | U1: FLL | V1: FLL.RANGO | W1: FLL.EQUIVALENCIA | X1: BORROSIDAD.VFP | Y1: BORROSIDAD.VFP.RANGO | Z1: BORROSIDAD.VFP.EQUIVALENCIA | AA1: VHL.BT1 | AB1: VHL.BT1.RANGO | AC1: VHL.BT1.EQUIVALENCIA | AD1: VHL.BT2 | AE1: VHL.BT2.RANGO | AF1: VHL.BT2.EQUIVALENCIA | AG1: VHL.BN1 | AH1: VHL.BN1.RANGO | AI1: VHL.BN1.EQUIVALENCIA | AJ1: VHL.BN2 | AK1: VHL.BN2.RANGO | AL1: VHL.BN2.EQUIVALENCIA | AM1: FVL | AN1: FVL.RANGO | AO1: FVL.EQUIVALENCIA | AP1: FLC | AQ1: FLC.RANGO | AR1: FLC.EQUIVALENCIA | AS1: ACA | AT1: ACA.RANGO | AU1: ACA.EQUIVALENCIA | AV1: CCF | AW1: CCF.RANGO | AX1: CCF.EQUIVALENCIA | AY1: FLCC | AZ1: FLCC.RANGO | BA1: FLCC.EQUIVALENCIA | BB1: VHC.BT1 | BC1: VHC.BT1.RANGO | BD1: VHC.BT1.EQUIVALENCIA | BE1: VHC.BT2 | BF1: VHC.BT2.RANGO | BG1: VHC.BT2.EQUIVALENCIA | BH1: VHC.BT3 | BI1: VHC.BT3.RANGO | BJ1: VHC.BT3.EQUIVALENCIA | BK1: VHC.BN1 | BL1: VHC.BN1.RANGO | BM1: VHC.BN1.EQUIVALENCIA | BN1: VHC.BN2 | BO1: VHC.BN2.RANGO | BP1: VHC.BN2.EQUIVALENCIA | BQ1: VHC.BN3 | BR1: VHC.BN3.RANGO | BS1: VHC.BN3.EQUIVALENCIA | BT1: FVC | BU1: FVC.RANGO | BV1: FVC.EQUIVALENCIA | BW1: AAOD | BX1: AAOD.formula.hofstetter | BY1: Dif.AAOD.hofstetter | BZ1: AAOD.RANGO | CA1: AAOD.EQUIVALENCIA | CB1: AAOI | CC1: AAOI.formula.hofstetter | CD1: Dif.AAOI.hofstetter | CE1: AAOI.RANGO | CF1: AAOI.EQUIVALENCIA | CG1: ARP | CH1: ARP.RANGO | CI1: ARP.EQUIVALENCIA | CJ1: ARN | CK1: ARN.RANGO | CL1: ARN.EQUIVALENCIA | CM1: EME.D | CN1: EME.D.VALOR | CO1: EME D LETRA | CP1: EME.I | CQ1: EME.I.VALOR | CR1: EME I LETRA | CS1: HIP.D | CT1: HIP.D.VALOR | CU1: HIP I LETRA | CV1: HIP.I | CW1: HIP.I.VALOR | CX1: HIP I LETRA | CY1: MIO.D | CZ1: MIO.D.VALOR | DA1: MIO D LETRA | DB1: MIO.I | DC1: MIO.I.VALOR | DD1: MIO I LETRA | DE1: AST.D | DF1: AST.D.VALOR | DG1: AST D LETRA | DH1: AST.I | DI1: AST.I.VALOR | DJ1: AST I LETRA | DK1: PRE.D | DL1: PRE.D.VALOR | DM1: PRE D LETRA | DN1: PRE.I | DO1: PRE.I.VALOR | DP1: PRE I LETRA | DQ1: DV.D | DR1: DV.I | DS1: REL | DT1: DR | DU1: A | DV1: A.valor | DW1: AUMENTO.HIP.D | DX1: AUMENTO.HIP.D.CATEGORÍA | DY1: AUMENTO.HIP.D.RANGO | DZ1: AUMENTO.HIP.I | EA1: AUMENTO.HIP.I.CATEGORÍA | EB1: AUMENTO.HIP.I.RANGO | EC1: AUMENTO.MIO.D | ED1: AUMENTO.MIO.D.CATEGORÍA | EE1: AUMENTO.MIO.D.RANGO | EF1: AUMENTO.MIO.I | EG1: AUMENTO.MIO.I.CATEGORÍA | EH1: AUMENTO.MIO.I.RANGO | EI1: AUMENTO.AST.D | EJ1: AUMENTO.AST.D.CATEGORÍA | EK1: AUMENTO.AST.D.RANGO | EL1: AUMENTO.AST.I | EM1: AUMENTO.AST.I.CATEGORÍA | EN1: AUMENTO.AST.I.RANGO | EO1: AUMENTO.PRE.D | EP1: AUMENTO.PRE.D.CATEGORÍA | EQ1: AUMENTO.PRE.D.RANGO | ER1: AUMENTO.PRE.I | ES1: AUMENTO.PRE.I.CATEGORÍA | ET1: AUMENTO.PRE.I.RANGO | EU1: T | EV1: RANGO.REVISIÓN | EW1: Nº.RANGO.REVISIÓN | EX1: EXISTENCIA DISFUNCIÓN | EY1: ANOMALÍAS VISUALES
A2: 1 | B2: 1 | C2: 36129 | E2: =VLOOKUP(A2,'286'!$A$3:$J$600,10,FALSE()) -> ABAD ANOVA, Mª CARMEN | F2: =VLOOKUP(A2,'286'!$A$3:$I$1768,3,FALSE()) -> AACAR | G2: =VLOOKUP(A2,'286'!$A$3:$I$1768,4,FALSE()) -> 25230 | H2: =YEAR(C2)-YEAR(G2) -> 29 | I2: =VLOOKUP(H2,LEYENDA!$C$2:$D$6,2,TRUE()) -> 25-40 | J2: =VLOOKUP(A2,'286'!$A$3:$I$1768,7,FALSE()) -> M | K2: =VLOOKUP(A2,'286'!$A$3:$I$1768,2,FALSE()) -> OD | L2: =VLOOKUP(A2,'286'!$A$3:$I$1768,8,FALSE()) -> D | M2: =VLOOKUP(A2,'286'!$A$3:$I$1768,9,FALSE()) -> D | N2: =IF(R2=O2, "MISMA","CONTRARIA") -> MISMA | O2: {=_xlfn.IFS(L2="D","1", L2="I","2")} -> 1 | P2: {=_xlfn.IFS(K2="OD","1", K2="OI","2")} -> 1 | Q2: {=_xlfn.IFS(J2="M","1", J2="H","2")} -> 1 | R2: {=_xlfn.IFS(M2="D","1", M2="I","2")} -> 1 | S2: {=_xlfn.IFS(N2="CONTRARIA", "1",N2= "MISMA","2")} -> 2 | T2: {=_xlfn.IFS(I2="0-12","1", I2="13-24","2", I2="25-40","3", I2="41-60","4", I2="61-100","5")} -> 3 | U2: 2 | V2: =IF(U2="","",IF(AND(U2>=-9,U2<=-6.5),"-9 a -6,5",IF(AND(U2>=-6,U2<=-3.5),"-6 a -3,5",IF(AND(U2>=-3,U2<=-1),"-3 a -1",IF(U2=-0.5,"-0,5",IF(AND(U2>=0,U2<=2.5),"0 a 2,5",IF(AND(U2>=3,U2<=5.5),"3 a 5,5",IF(AND(U2>=6,U2<=8.5),"6 a 8,5",IF(AND(U2>=9,U2<=20),"9 a 20","Fuera de rango"))))))))) -> 0 a 2,5 | W2: =IF(V2="","",IF(V2="-9 a -6,5",2,IF(V2="-6 a -3,5",3,IF(V2="-3 a -1",4,IF(V2="-0,5","NORMA",IF(V2="0 a 2,5",5,IF(V2="3 a 5,5",6,IF(V2="6 a 8,5",7,IF(V2="9 a 20",8,"Fuera de rango"))))))))) -> 5 | X2: 12 | Y2: =IF(X2="","",IF(AND(X2>=0,X2<=4),"0 a 4",IF(AND(X2>=4.5,X2<=8.5),"4,5 a 8,5",IF(X2=9,"9",IF(AND(X2>=9.5,X2<=13),"9,5 a 13",IF(AND(X2>=13.5,X2<=20),"13,5 a 20",IF(AND(X2>=20.5,X2<=35),"20,5 a 35","Fuera de rango"))))))) -> 9,5 a 13 | Z2: =IF(Y2="","",IF(Y2="0 a 4",1,IF(Y2="4,5 a 8,5",2,IF(Y2="9","NORMA",IF(Y2="9,5 a 13",3,IF(Y2="13,5 a 20",4,IF(Y2="20,5 a 35",5,"Fuera de rango"))))))) -> 3 | AA2: 19 | AB2: =IF(AA2="","",IF(AND(AA2>=0,AA2<=9),"0 a 9",IF(AND(AA2>=9.5,AA2<=18.5),"9,5 a 18,5",IF(AA2=19,"19",IF(AND(AA2>=19.5,AA2<=28),"19,5 a 28",IF(AND(AA2>=28.5,AA2<=40),"28,5 a 40","Fuera de rango")))))) -> 19 | AC2: {=_xlfn.IFS(AB2="","",AB2="0 a 9",1,AB2="9,5 a 18,5",2,AB2="19","NORMA",AB2="19,5 a 28",3,AB2="28,5 a 40",4,TRUE(),"Fuera de rango")} -> NORMA | AD2: 13 | AE2: =IF(AD2="","",IF(AND(AD2>=-10,AD2<=0),"De -10 a 0",IF(AND(AD2>=0.5,AD2<=9.5),"0,5 a 9,5",IF(AD2=10,"10",IF(AND(AD2>=10.5,AD2<=20),"10,5 a 20",IF(AND(AD2>=20.5,AD2<=40),"20,5 a 40","Fuera de rango")))))) -> 10,5 a 20 | AF2: =IF(AD2="","",IF(AND(AD2>=-10,AD2<=0),1,IF(AND(AD2>=0.5,AD2<=9.5),2,IF(AD2=10,"NORMA",IF(AND(AD2>=10.5,AD2<=20),3,IF(AND(AD2>=20.5,AD2<=40),4,"")))))) -> 3 | AH2: =IF(AG2="","",IF(AND(AG2>=0,AG2<=4),"0 a 4",IF(AND(AG2>=4.5,AG2<=8.5),"4,5 a 8,5",IF(AG2=9,"9",IF(AND(AG2>=9.5,AG2<=13),"9,5 a 13",IF(AND(AG2>=13.5,AG2<=25),"13,5 a 25","Fuera de rango")))))) | AI2: =IF(AH2="","",IF(AH2="0 a 4",1,IF(AH2="4,5 a 8,5",2,IF(AH2="9","NORMA",IF(AH2="9,5 a 13",3,IF(AH2="13,5 a 25",4,"")))))) | AJ2: 3 | AK2: =IF(AJ2="","",IF(AND(AJ2>=-15,AJ2<=-10.5),"-15 a -10,5",IF(AND(AJ2>=-10,AJ2<=-4),"-10 a -4",IF(AND(AJ2>=-4.5,AJ2<=0),"-4,5 a 0",IF(AND(AJ2>=0.5,AJ2<=4.5),"0,5 a 4,5",IF(AJ2=5,"5",IF(AND(AJ2>=5.5,AJ2<=10),"5,5 a 10",IF(AND(AJ2>=10.5,AJ2<=20),"10,5 a 20","Fuera de rango")))))))) -> 0,5 a 4,5 | AL2: =IF(AK2="","",IF(AK2="-15 a -10,5",1,IF(AK2="-10 a -4",2,IF(AK2="-4,5 a 0",3,IF(AK2="0,5 a 4,5",4,IF(AK2="5","NORMA",IF(AK2="5,5 a 10",5,IF(AK2="10,5 a 20",6,"Error")))))))) -> 4 | AM2: 0 | AN2: =IF(AM2="","",IF(AND(AM2>=-7.5,AM2<=-5.5),"-7,5 a -5,5",IF(AND(AM2>=-5,AM2<=-3),"-5 a -3",IF(AND(AM2>=-2.5,AM2<=-0.5),"-2,5 a -0,5",IF(AM2=0,"0,00",IF(AND(AM2>=0.5,AM2<=2.5),"0,5 a 2,5",IF(AND(AM2>=3,AM2<=5),"3 a 5",IF(AND(AM2>=5.5,AM2<=7.5),"5,5 a 7,5",IF(AND(AM2>=8,AM2<=10),"8 a 10","Fuera de rango"))))))))) -> 0,00 | AO2: =IF(AN2="","",IF(AN2="-7,5 a -5,5",1,IF(AN2="-5 a -3",2,IF(AN2="-2,5 a -0,5",3,IF(AN2="0,00","NORMA",IF(AN2="0,5 a 2,5",4,IF(AN2="3 a 5",5,IF(AN2="5,5 a 7,5",6,IF(AN2="8 a 10",7,"Error"))))))))) -> NORMA | AP2: 4 | AQ2: =IF(AP2="","",IF(AND(AP2>=-20,AP2<=-9.5),"-20 a -9,5",IF(AND(AP2>=-9,AP2<=-6.5),"-9 a -6,5",IF(AP2=-6,"-6",IF(AND(AP2>=-5.5,AP2<=-3),"-5,5 a -3",IF(AND(AP2>=-2.5,AP2<=0),"-2,5 a 0",IF(AND(AP2>=0.5,AP2<=3),"0,5 a 3",IF(AND(AP2>=3.5,AP2<=6),"3,5 a 6",IF(AND(AP2>=6.5,AP2<=9),"6,5 a 9",IF(AND(AP2>=9.5,AP2<=20),"9,5 a 20","Fuera de rango")))))))))) -> 3,5 a 6 | AR2: =IF(AQ2="","",IF(AQ2="-20 a -9,5",1,IF(AQ2="-9 a -6,5",2,IF(AQ2="-6","NORMA",IF(AQ2="-5,5 a -3",3,IF(AQ2="-2,5 a 0",4,IF(AQ2="0,5 a 3",5,IF(AQ2="3,5 a 6",6,IF(AQ2="6,5 a 9",7,IF(AQ2="9,5 a 20",8,"")))))))))) -> 6 | AS2: 3 | AT2: =IF(AS2="","",IF(AND(AS2>=-16,AS2<=-14),"-16 a -14",IF(AND(AS2>=-13.5,AS2<=-11.5),"-13,5 a -11,5",IF(AND(AS2>=-11,AS2<=-9),"-11 a -9",IF(AND(AS2>=-8.5,AS2<=-6.5),"-8,5 a -6,5",IF(AND(AS2>=-6,AS2<=-4),"-6 a -4",IF(AND(AS2>=-3.5,AS2<=-1.5),"-3,5 a -1,5",IF(AND(AS2>=-1,AS2<=1),"-1 a 1",IF(AND(AS2>=1.5,AS2<=3.5),"1,5 a 3,5",IF(AND(AS2>=4,AS2<=6),"4 a 6",IF(AND(AS2>=6.5,AS2<=8.5),"6,5 a 8,5",IF(AND(AS2>=9,AS2<=11),"9 a 11",IF(AND(AS2>=11.5,AS2<=13.5),"11,5 a 13,5",IF(AND(AS2>=14,AS2<=16),"14 a 16",IF(AND(AS2>=16.5,AS2<=18.5),"16,5 a 18,5",IF(AND(AS2>=19,AS2<=21),"19 a 21","Fuera de rango")))))))))))))))) -> 1,5 a 3,5 | AU2: {=IF(AT2="","",_xlfn.IFS(AT2="-16 a -14",1,AT2="-13,5 a -11,5",2,AT2="-11 a -9",3,AT2="-8,5 a -6,5",4,AT2="-6 a -4",5,AT2="-3,5 a -1,5",6,AT2="-1 a 1",7,AT2="1,5 a 3,5",8,AT2="4 a 6","NORMA",AT2="6,5 a 8,5",9,AT2="9 a 11",10,AT2="11,5 a 13,5",11,AT2="14 a 16",12,AT2="16,5 a 18,5",13,AT2="19 a 21",14,TRUE(),""))} -> 8 | AV2: 0.25 | AW2: =IF(AV2="","",IF(AND(AV2>=-1,AV2<=-0.5),"-1 a -0,5",IF(AND(AV2>-0.5,AV2<=0),"De -0,5 a 0",IF(AND(AV2>=0.25,AV2<=0.75),"0,25 a 0,75",IF(AND(AV2>=1,AV2<=1.5),"1 a 1,5",IF(AND(AV2>=1.75,AV2<=2.25),"1,75 a 2,25",IF(AND(AV2>=2.5,AV2<=3),"2,5 a 3",IF(AND(AV2>=3.25,AV2<=3.75),"3,25 a 3,75","Fuera de rango")))))))) -> 0,25 a 0,75 | AX2: =IF(AW2="","",IF(OR(AW2="-1 a -0,5",AW2="-1 a -0.5"),1,IF(OR(AW2="De -0,5 a 0",AW2="-0,5 a 0",AW2="De -0.5 a 0"),2,IF(OR(AW2="0,25 a 0,75",AW2="0.25 a 0.75"),"NORMA",IF(OR(AW2="1 a 1,5",AW2="1 a 1.5"),3,IF(OR(AW2="1,75 a 2,25",AW2="1.75 a 2.25"),4,IF(OR(AW2="2,5 a 3",AW2="2.5 a 3"),5,IF(OR(AW2="3,25 a 3,75",AW2="3.25 a 3.75"),6,"")))))))) -> NORMA | AY2: 4 | AZ2: =IF(AY2="","",IF(AND(AY2>=-20,AY2<=-9.5),"-20 a -9,5",IF(AND(AY2>=-9,AY2<=-6.5),"-9 a -6,5",IF(AY2=-6,"-6",IF(AND(AY2>=-5.5,AY2<=-3),"-5,5 a -3",IF(AND(AY2>=-2.5,AY2<=0),"-2,5 a 0",IF(AND(AY2>=0.5,AY2<=3),"0,5 a 3",IF(AND(AY2>=3.5,AY2<=6),"3,5 a 6","Fuera de rango")))))))) -> 3,5 a 6 | BA2: =IF(AZ2="","",IF(AZ2="-20 a -9,5",1,IF(AZ2="-9 a -6,5",2,IF(AZ2="-6","NORMA",IF(AZ2="-5,5 a -3",3,IF(AZ2="-2,5 a 0",4,IF(AZ2="0,5 a 3",5,IF(AZ2="3,5 a 6",6,"")))))))) -> 6 | BB2: 0 | BC2: {=IF(BB2="","",_xlfn.IFS(AND(BB2>=0,BB2<=2),"0 a 2",AND(BB2>=2.5,BB2<=4.5),"2,5 a 4,5",AND(BB2>=5,BB2<=7),"5 a 7",AND(BB2>=7.5,BB2<=9.5),"7,5 a 9,5",AND(BB2>=10,BB2<=12),"10 a 12",AND(BB2>=12.5,BB2<=14.5),"12,5 a 14,5",BB2=15,"15",AND(BB2>=15.5,BB2<=17.5),"15,5 a 17,5",AND(BB2>=18,BB2<=20),"18 a 20",AND(BB2>=20.5,BB2<=22.5),"20,5 a 22,5",AND(BB2>=23,BB2<=25),"23 a 25",TRUE(),"Fuera de rango"))} -> 0 a 2 | BD2: {=IF(BC2="","",_xlfn.IFS(BC2="0 a 2",1,BC2="2,5 a 4,5",2,BC2="5 a 7",3,BC2="7,5 a 9,5",4,BC2="10 a 12",5,BC2="12,5 a 14,5",6,BC2="15","NORMA",BC2="15,5 a 17,5",7,BC2="18 a 20",8,BC2="20,5 a 22,5",9,BC2="23 a 25",10,TRUE(),"Fuera de rango"))} -> 1 | BE2: 22 | BF2: =IF(BE2="","",IF(AND(BE2>=-20,BE2<=-10),"-20 a -10",IF(AND(BE2>=-9.5,BE2<=0.5),"-9,5 a 0,5",IF(AND(BE2>=1,BE2<=11),"1 a 11",IF(AND(BE2>=11.5,BE2<=20.5),"11,5 a 20,5",IF(BE2=21,"21",IF(AND(BE2>=21.5,BE2<=31.5),"21,5 a 31,5",IF(AND(BE2>=32,BE2<=42),"32 a 42","Fuera de rango")))))))) -> 21,5 a 31,5 | BG2: =IF(BF2="","",IF(BF2="-20 a -10",1,IF(BF2="-9,5 a 0,5",2,IF(BF2="1 a 11",3,IF(BF2="11,5 a 20,5",4,IF(BF2="21","NORMA",IF(BF2="21,5 a 31,5",5,IF(BF2="32 a 42",6,"")))))))) -> 5 | BH2: 16 | BI2: =IF(BH2="","",IF(AND(BH2>=-20,BH2<=-15),"-20 a -15",IF(AND(BH2>=-14.5,BH2<=-9.5),"-14,5 a -9,5",IF(AND(BH2>=-9,BH2<=-4),"-9 a -4",IF(AND(BH2>=-3.5,BH2<=2.5),"-3,5 a 2,5",IF(AND(BH2>=3,BH2<=8),"3 a 8",IF(AND(BH2>=8.5,BH2<=14.5),"8,5 a 14,5",IF(BH2=15,"15",IF(AND(BH2>=15.5,BH2<=20.5),"15,5 a 20,5",IF(AND(BH2>=21,BH2<=26),"21 a 26","Fuera de rango")))))))))) -> 15,5 a 20,5 | BJ2: =IF(BI2="","",IF(BI2="-20 a -15",1,IF(BI2="-14,5 a -9,5",2,IF(BI2="-9 a -4",3,IF(BI2="-3,5 a 2,5",4,IF(BI2="3 a 8",5,IF(BI2="8,5 a 14,5",6,IF(BI2="15","NORMA",IF(BI2="15,5 a 20,5",7,IF(BI2="21 a 26",8,IF(BI2="26,5 a 31,5",9,""))))))))))) -> 7 | BK2: 0 | BL2: =IF(BK2="","",IF(AND(BK2>=0,BK2<=2),"0 - 2",IF(AND(BK2>=2.5,BK2<=4.5),"2,5 - 4,5",IF(AND(BK2>=5,BK2<=7),"5 - 7",IF(AND(BK2>=7.5,BK2<=9.5),"7,5 - 9,5",IF(AND(BK2>=10,BK2<=12),"10 - 12",IF(AND(BK2>=12.5,BK2<=13.5),"12,5 - 13,5",IF(BK2=14,"14",IF(AND(BK2>=14.5,BK2<=16.5),"14,5 - 16,5",IF(AND(BK2>=17,BK2<=19),"17 - 19",IF(AND(BK2>=19.5,BK2<=21.5),"19,5 - 21,5",IF(AND(BK2>=22,BK2<=24),"22 - 24",IF(AND(BK2>=24.5,BK2<=26.5),"24,5 - 26,5",IF(AND(BK2>=27,BK2<=29),"27 - 29",IF(AND(BK2>=29.5,BK2<=30),"29,5 - 30","Fuera de rango"))))))))))))))) -> 0 - 2 | BM2: =IF(BL2="","",IF(BL2="0 - 2",1,IF(BL2="2,5 - 4,5",2,IF(BL2="5 - 7",3,IF(BL2="7,5 - 9,5",4,IF(BL2="10 - 12",5,IF(BL2="12,5 - 13,5",6,IF(BL2="14","NORMA",IF(BL2="14,5 - 16,5",7,IF(BL2="17 - 19",8,IF(BL2="19,5 - 21,5",9,IF(BL2="22 - 24",10,IF(BL2="24,5 - 26,5",11,IF(BL2="27 - 29",12,IF(BL2="29,5 - 30",13,""))))))))))))))) -> 1 | BN2: 15 | BO2: =IF(BN2="","",IF(AND(BN2>=-20,BN2<=-10),"-20 a -10",IF(AND(BN2>=-9.5,BN2<=0.5),"-9,5 a 0,5",IF(AND(BN2>=1,BN2<=11),"1 a 11",IF(AND(BN2>=11.5,BN2<=21.5),"11,5 a 21,5",IF(BN2=22,"22",IF(AND(BN2>=22.5,BN2<=32.5),"22,5 a 32,5",IF(AND(BN2>=33,BN2<=43),"33 a 43","Fuera de rango")))))))) -> 11,5 a 21,5 | BP2: =IF(BO2="","",IF(BO2="-20 a -10",1,IF(BO2="-9,5 a 0,5",2,IF(BO2="1 a 11",3,IF(BO2="11,5 a 21,5",4,IF(BO2="22","NORMA",IF(BO2="22,5 a 32,5",5,IF(BO2="33 a 43",6,"")))))))) -> 4 | BQ2: 8 | BR2: =IF(BQ2="","",IF(AND(BQ2>=-20,BQ2<=-15),"-20 a -15",IF(AND(BQ2>=-14.5,BQ2<=-9.5),"-14,5 a -9,5",IF(AND(BQ2>=-9,BQ2<=-4),"-9 a -4",IF(AND(BQ2>=-3.5,BQ2<=2.5),"-3,5 a 2,5",IF(AND(BQ2>=3,BQ2<=8),"3 a 8",IF(AND(BQ2>=8.5,BQ2<=13.5),"8,5 a 13,5",IF(AND(BQ2>=14,BQ2<=17.5),"14 a 17,5",IF(BQ2=18,"18",IF(AND(BQ2>=18.5,BQ2<=23.5),"18,5 a 23,5",IF(AND(BQ2>=24,BQ2<=29),"24 a 29",IF(AND(BQ2>=29.5,BQ2<=34.5),"29,5 a 34,5",IF(AND(BQ2>=35,BQ2<=40),"35 a 40","Fuera de rango"))))))))))))) -> 3 a 8 | BS2: =IF(BR2="","",IF(BR2="-20 a -15",1,IF(BR2="-14,5 a -9,5",2,IF(BR2="-9 a -4",3,IF(BR2="-3,5 a 2,5",4,IF(BR2="3 a 8",5,IF(BR2="8,5 a 13,5",6,IF(BR2="14 a 17,5",7,IF(BR2="18","NORMA",IF(BR2="18,5 a 23,5",8,IF(BR2="24 a 29",9,IF(BR2="29,5 a 34,5",10,IF(BR2="35 a 40",11,""))))))))))))) -> 5 | BT2: -1 | BU2: =IF(BT2="","",IF(AND(BT2>=-20,BT2<=-18),"-20 a -18",IF(AND(BT2>=-17.5,BT2<=-15.5),"-17,5 a -15,5",IF(AND(BT2>=-15,BT2<=-13),"-15 a -13",IF(AND(BT2>=-12.5,BT2<=-10.5),"-12,5 a -10,5",IF(AND(BT2>=-10,BT2<=-8),"-10 a -8",IF(AND(BT2>=-7.5,BT2<=-5.5),"-7,5 a -5,5",IF(AND(BT2>=-5,BT2<=-3),"-5 a -3",IF(AND(BT2>=-2.5,BT2<=-0.5),"-2,5 a -0,5",IF(BT2=0,"0",IF(AND(BT2>=0.5,BT2<=2.5),"0,5 a 2,5",IF(AND(BT2>=3,BT2<=5),"3 a 5",IF(AND(BT2>=5.5,BT2<=7.5),"5,5 a 7,5",IF(AND(BT2>=8,BT2<=10),"8 a 10",IF(AND(BT2>=10.5,BT2<=12.5),"10,5 a 12,5",IF(AND(BT2>=13,BT2<=15),"13 a 15",IF(AND(BT2>=15.5,BT2<=17.5),"15,5 a 17,5",IF(AND(BT2>=18,BT2<=20),"18 a 20","Fuera de rango")))))))))))))))))) -> -2,5 a -0,5 | BV2: =IF(BT2="","",IF(BT2=0,"NORMA",IF(AND(BT2>=-20,BT2<=-18),2,IF(AND(BT2>=-17.5,BT2<=-15.5),2,IF(AND(BT2>=-15,BT2<=-13),3,IF(AND(BT2>=-12.5,BT2<=-10.5),4,IF(AND(BT2>=-10,BT2<=-8),5,IF(AND(BT2>=-7.5,BT2<=-5.5),6,IF(AND(BT2>=-5,BT2<=-3),7,IF(AND(BT2>=-2.5,BT2<=-0.5),8,IF(AND(BT2>=0.5,BT2<=2.5),9,IF(AND(BT2>=3,BT2<=5),10,IF(AND(BT2>=5.5,BT2<=7.5),11,IF(AND(BT2>=8,BT2<=10),12,IF(AND(BT2>=10.5,BT2<=12.5),13,IF(AND(BT2>=13,BT2<=15),14,IF(AND(BT2>=15.5,BT2<=17.5),15,IF(AND(BT2>=18,BT2<=20),16,"Fuera de rango")))))))))))))))))) -> 8 | BW2: -3.25 | BX2: =18.5- (0.3*H2) -> 9.8 | BY2: =(BW2)-(BX2) -> -13.05 | BZ2: =IF(BY2="","",IF(BY2<-27.5,"De -30 a -28",IF(BY2<-25,"De -27,5 a -25,5",IF(BY2<-22.5,"De -25 a -23",IF(BY2<-20,"De -22,5 a -20,5",IF(BY2<-17.5,"De -20 a -18",IF(BY2<-15,"De -17,5 a -15,5",IF(BY2<-12.5,"De -15 a -13",IF(BY2<-10,"De -12,5 a -10,5",IF(BY2<-7.5,"De -10 a -8",IF(BY2<-5,"De -7,5 a -5,5",IF(BY2<-2.5,"De -5 a -3",IF(BY2<0,"De -2,5 a -0,5",IF(BY2<2.5,"De 0 a 2",IF(BY2<5,"De 2,5 a 4,5",IF(BY2<7.5,"De 5 a 7",IF(BY2<10,"De 7,5 a 9,5",IF(BY2<12.5,"De 10 a 12",IF(BY2<15,"De 12,5 a 14,5",IF(BY2<17.5,"De 15 a 17",IF(BY2<20,"De 17,5 a 19,5",IF(BY2<22.5,"De 20 a 22",IF(BY2<25,"De 22,5 a 24,5",IF(BY2<27.5,"De 25 a 27","De 27,5 a 30")))))))))))))))))))))))) -> De -15 a -13 | CA2: =IF(BY2="","",IF(BY2<=-28,1,IF(BY2<=-25.5,2,IF(BY2<=-23,3,IF(BY2<=-20.5,4,IF(BY2<=-18,5,IF(BY2<=-15.5,6,IF(BY2<=-13,7,IF(BY2<=-10.5,8,IF(BY2<=-8,9,IF(BY2<=-5.5,10,IF(BY2<=-3,11,IF(BY2<=-0.5,12,IF(BY2<=2,13,IF(BY2<=4.5,14,IF(BY2<=7,15,IF(BY2<=9.5,16,IF(BY2<=12,17,IF(BY2<=14.5,18,IF(BY2<=17,19,IF(BY2<=19.5,20,IF(BY2<=22,21,IF(BY2<=24.5,22,IF(BY2<=27,23,IF(BY2<=30,24,"Fuera de rango"))))))))))))))))))))))))) -> 7 | CB2: -3.25 | CC2: =18.5- (0.3*H2) -> 9.8 | CD2: =(CB2)-(CC2) -> -13.05 | CE2: =IF(CD2="","",IF(CD2<-27.5,"De -30 a -28",IF(CD2<-25,"De -27,5 a -25,5",IF(CD2<-22.5,"De -25 a -23",IF(CD2<-20,"De -22,5 a -20,5",IF(CD2<-17.5,"De -20 a -18",IF(CD2<-15,"De -17,5 a -15,5",IF(CD2<-12.5,"De -15 a -13",IF(CD2<-10,"De -12,5 a -10,5",IF(CD2<-7.5,"De -10 a -8",IF(CD2<-5,"De -7,5 a -5,5",IF(CD2<-2.5,"De -5 a -3",IF(CD2<0,"De -2,5 a -0,5",IF(CD2<=2,"De 0 a 2",IF(CD2<=4.5,"De 2,5 a 4,5",IF(CD2<=7,"De 5 a 7",IF(CD2<=9.5,"De 7,5 a 9,5",IF(CD2<=12,"De 10 a 12",IF(CD2<=14.5,"De 12,5 a 14,5",IF(CD2<=17,"De 15 a 17",IF(CD2<=19.5,"De 17,5 a 19,5",IF(CD2<=22,"De 20 a 22",IF(CD2<=24.5,"De 22,5 a 24,5",IF(CD2<=27,"De 25 a 27","De 27,5 a 30")))))))))))))))))))))))) -> De -15 a -13 | CF2: =IF(CD2="","",IF(CD2<-27.5,1,IF(CD2<-25,2,IF(CD2<-22.5,3,IF(CD2<-20,4,IF(CD2<-17.5,5,IF(CD2<-15,6,IF(CD2<-12.5,7,IF(CD2<-10,8,IF(CD2<-7.5,9,IF(CD2<-5,10,IF(CD2<-2.5,11,IF(CD2<0,12,IF(CD2<2.5,13,IF(CD2<5,14,IF(CD2<7.5,15,IF(CD2<10,16,IF(CD2<12.5,17,IF(CD2<15,18,IF(CD2<17.5,19,IF(CD2<20,20,IF(CD2<22.5,21,IF(CD2<25,22,IF(CD2<27.5,23,24)))))))))))))))))))))))) -> 7 | CG2: -1 | CH2: =IF(CG2="","",IF(AND(CG2>=-10,CG2<=-9.5),"-10 a -9,5",IF(AND(CG2>-9.5,CG2<=-8.5),"-9 a -8,5",IF(AND(CG2>-8.5,CG2<=-7.5),"-8 a -7,5",IF(AND(CG2>-7.5,CG2<=-6.5),"-7 a -6,5",IF(AND(CG2>-6.5,CG2<=-5.5),"-6 a -5,5",IF(AND(CG2>-5.5,CG2<=-4.5),"-5 a -4,5",IF(AND(CG2>-4.5,CG2<=-3.5),"-4 a -3,5",IF(AND(CG2>-3.5,CG2<=-2.5),"-3 a -2,5",IF(CG2=-2.25,"-2,25",IF(AND(CG2>-2.5,CG2<=-1.5),"-2 a -1,5",IF(AND(CG2>-1.5,CG2<=-0.5),"-1 a -0,5",IF(AND(CG2>-0.5,CG2<=0.5),"0 a 0,5",IF(AND(CG2>0.5,CG2<=1.5),"1 a 1,5",IF(AND(CG2>1.5,CG2<=2.5),"2 a 2,5",IF(AND(CG2>2.5,CG2<=3.5),"3 a 3,5",IF(AND(CG2>3.5,CG2<=4.5),"4 a 4,5",IF(AND(CG2>4.5,CG2<=5.5),"5 a 5,5",IF(AND(CG2>5.5,CG2<=6.5),"6 a 6,5",IF(AND(CG2>6.5,CG2<=7.5),"7 a 7,5",IF(AND(CG2>7.5,CG2<=8.5),"8 a 8,5",IF(AND(CG2>8.5,CG2<=9.5),"9 a 9,5",IF(CG2>=10,"10","Fuera de rango"))))))))))))))))))))))) -> -1 a -0,5 | CI2: =IF(CG2="","",IF(CG2=-2.25,"NORMA",IF(CG2<=-9.5,1,IF(CG2<=-8.5,2,IF(CG2<=-7.5,3,IF(CG2<=-6.5,4,IF(CG2<=-5.5,5,IF(CG2<=-4.5,6,IF(CG2<=-3.5,7,IF(CG2<=-2.5,8,IF(CG2<=-1.5,9,IF(CG2<=-0.5,10,IF(CG2<=0.5,11,IF(CG2<=1.5,12,IF(CG2<=2.5,13,IF(CG2<=3.5,14,IF(CG2<=4.5,15,IF(CG2<=5.5,16,IF(CG2<=6.5,17,IF(CG2<=7.5,18,IF(CG2<=8.5,19,IF(CG2<=9.5,20,IF(CG2=10,21,"Fuera de rango"))))))))))))))))))))))) -> 10 | CJ2: 0.75 | CK2: =IF(CJ2="","",IF(AND(CJ2>=-6,CJ2<=-5.5),"-6 a -5,5",IF(AND(CJ2>-5.5,CJ2<=-4.5),"-5 a -4,5",IF(AND(CJ2>-4.5,CJ2<=-3.5),"-4 a -3,5",IF(AND(CJ2>-3.5,CJ2<=-2.5),"-3 a -2,5",IF(AND(CJ2>-2.5,CJ2<=-1.5),"-2 a -1,5",IF(AND(CJ2>-1.5,CJ2<=-0.5),"-1 a -0,5",IF(AND(CJ2>-0.5,CJ2<=0.5),"0 a 0,5",IF(AND(CJ2>0.5,CJ2<=1.5),"1 a 1,5",IF(AND(CJ2>1.5,CJ2<2.5),"2",IF(AND(CJ2>=2.5,CJ2<=3),"2,5 a 3",IF(AND(CJ2>3,CJ2<=4),"3,5 a 4",IF(AND(CJ2>4,CJ2<=5),"4,5 a 5",IF(AND(CJ2>5,CJ2<=6),"5,5 a 6",IF(AND(CJ2>6,CJ2<=7),"6,5 a 7",IF(AND(CJ2>7,CJ2<=8),"7,5 a 8",IF(AND(CJ2>8,CJ2<=9.5),"8,5 a 9,5",IF(CJ2=10,"10","Fuera de rango")))))))))))))))))) -> 1 a 1,5 | CL2: =IF(CK2="","",IF(OR(CK2="-6 a -5,5",CK2="-6 - -5,5"),1,IF(OR(CK2="-5 a -4,5",CK2="-5 - -4,5"),2,IF(OR(CK2="-4 a -3,5",CK2="-4 - -3,5"),3,IF(OR(CK2="-3 a -2,5",CK2="-3 - -2,5"),4,IF(OR(CK2="-2 a -1,5",CK2="-2 - -1,5"),5,IF(OR(CK2="-1 a -0,5",CK2="-1 - -0,5"),6,IF(OR(CK2="0 a 0,5",CK2="0 - 0,5"),7,IF(OR(CK2="1 a 1,5",CK2="1 - 1,5"),8,IF(CK2="2","NORMA",IF(OR(CK2="2,5 a 3",CK2="2,5 - 3"),9,IF(OR(CK2="3,5 a 4",CK2="3,5 - 4"),10,IF(OR(CK2="4,5 a 5",CK2="4,5 - 5"),11,IF(OR(CK2="5,5 a 6",CK2="5,5 - 6"),12,IF(OR(CK2="6,5 a 7",CK2="6,5 - 7"),13,IF(OR(CK2="7,5 a 8",CK2="7,5 - 8"),14,IF(OR(CK2="8,5 a 9",CK2="8,5 - 9,5",CK2="9 a 9,5"),15,IF(CK2="10",15,IF(OR(CK2="0,5 a 1",CK2="0,5 - 1"),7,"Fuera de rango"))))))))))))))))))) -> 8 | CM2: 0 | CN2: =IF(CM2=0,"0", " ") -> 0 | CO2: =IF(CM2>0,"EME"," ") | CP2: 0 | CQ2: =IF(CP2>0,"0", " ") | CR2: =IF(CP2>0,"EME"," ") | CS2: 0 | CT2: =IF(CS2>0,"1", " ") | CU2: =IF(CS2>0,"HIP"," ") | CV2: 0 | CW2: =IF(CV2>0,"1", " ") | CX2: =IF(CV2>0,"HIP"," ") | CY2: -1.25 | CZ2: =IF(CY2<0,"2"," ") -> 2 | DA2: =IF(CY2<0,"MIO"," ") -> MIO | DB2: -1.75 | DC2: =IF(DB2<0,"2"," ") -> 2 | DD2: =IF(DB2<0,"MIO"," ") -> MIO | DE2: -0.25 | DF2: =IF(DE2<0,"3"," ") -> 3 | DG2: =IF(DE2<0,"AST"," ") -> AST | DH2: -0.5 | DI2: =IF(DH2<0,"3"," ") -> 3 | DJ2: =IF(DH2<0,"AST"," ") -> AST | DK2: 0 | DL2: =IF(DK2>0,"4"," ") | DM2: =IF(DK2>0,"PRE"," ") | DN2: 0 | DO2: =IF(DN2>0,"4"," ") | DP2: =IF(DN2>0,"PRE"," ") | DQ2: 2 | DR2: 2 | DS2: =CONCATENATE(CO2,CU2,DA2,DG2,DM2) -> MIOAST | DT2: {=_xlfn.IFS(DS2="EME ","0", DS2=" HIP ","1", DS2=" MIO ","2", DS2=" AST ","3", DS2=" PRE","4", DS2="EME PRE","5", DS2=" HIP PRE","6", DS2=" HIP AST ","7", DS2=" MIO PRE","8", DS2=" MIOAST ","9", DS2=" ASTPRE","10",DS2=" HIP ASTPRE","11", DS2=" MIOASTPRE","12", DS2=" ","0")} -> 9 | DU2: SI | DV2: {=_xlfn.IFS(DU2="SI","2", DU2="NO","1")} -> 2 | DW2: 0 | DX2: =IF(DW2=0,"1","2") -> 1 | DY2: {=_xlfn.IFS(DW2=0,"0", DW2=0.25, "1", DW2=0.5,"2", DW2=0.75,"3", DW2=1,"4",DW2=1.25,"5", DW2=1.5,"6", DW2=1.75,"7", DW2=2,"8", DW2=2.25,"9",DW2=2.5,"10", DW2=2.75,"11", DW2=3,"12", DW2=3.25,"13", DW2=3.5,"14", DW2=3.75,"15",DW2=4,"16")} -> 0 | DZ2: 0 | EA2: =IF(DZ2=0,"1","2") -> 1 | EB2: {=_xlfn.IFS(DZ2=0,"0", DZ2=0.25, "1", DZ2=0.5,"2", DZ2=0.75,"3", DZ2=1,"4",DZ2=1.25,"5", DZ2=1.5,"6", DZ2=1.75,"7", DZ2=2,"8")} -> 0 | EC2: -0.5 | ED2: =IF(EC2=0,"1","2") -> 2 | EE2: {=_xlfn.IFS(EC2=0,"0", EC2=-0.25, "1", EC2=-0.5,"2", EC2=-0.75,"3", EC2=-1,"4",EC2=-1.25,"5", EC2=-1.5,"6", EC2=-1.75,"7", EC2=-2,"8", EC2=-2.25,"9",EC2=-2.5,"10", EC2=-2.75,"11", EC2=-3,"12", EC2=-3.25,"13", EC2=-3.5,"14", EC2=-3.75,"15",EC2=-4,"16")} -> 2 | EF2: -0.5 | EG2: =IF(EF2=0,"1","2") -> 2 | EH2: {=_xlfn.IFS(EF2=0,"0", EF2=-0.25, "1", EF2=-0.5,"2", EF2=-0.75,"3", EF2=-1,"4",EF2=-1.25,"5", EF2=-1.5,"6", EF2=-1.75,"7", EF2=-2,"8", EF2=-2.25,"9",EF2=-2.5,"10", EF2=-2.75,"11", EF2=-3,"12", EF2=-3.25,"13", EF2=-3.5,"14", EF2=-3.75,"15",EF2=-4,"16")} -> 2 | EI2: -0.25 | EJ2: =IF(EI2=0,"1","2") -> 2 | EK2: {=_xlfn.IFS(EI2=0,"0", EI2=-0.25, "1", EI2=-0.5,"2", EI2=-0.75,"3", EI2=-1,"4",EI2=-1.25,"5", EI2=-1.5,"6", EI2=-1.75,"7", EI2=-2,"8", EI2=-2.25,"9", EI2=-2.25,"9",EI2=-2.5,"10", EI2=-2.75,"11", EI2=-3,"12", EI2=-3.25,"13", EI2=-3.5,"14", EI2=-3.75,"15",EI2=-4,"16", EI2=0.25, "17", EI2=0.5, "18")} -> 1 | EL2: 0 | EM2: =IF(EL2=0,"1","2") -> 1 | EN2: {=_xlfn.IFS(EL2=0.25,"17",EL2=0.5,"18", EL2=0,"0", EL2=-0.25, "1", EL2=-0.5,"2", EL2=-0.75,"3", EL2=-1,"4",EL2=-1.25,"5", EL2=-1.5,"6", EL2=-1.75,"7", EL2=-2,"8",EL2= -2.25,"9",EL2=-2.5,"10",EL2= -2.75,"11",EL2= -3,"12",EL2= -3.25,"13",EL2= -3.5,"14",EL2= -3.75,"15",EL2=-4,"16")} -> 0 | EO2: 0 | EP2: =IF(EO2=0,"1","2") -> 1 | EQ2: {=_xlfn.IFS(EO2=0,"0", EO2=0.25, "1", EO2=0.5,"2", EO2=0.75,"3", EO2=1,"4",EO2=1.25,"5", EO2=1.5,"6", EO2=1.75,"7", EO2=2,"8", EO2=2.25,"9", EO2=2.25,"9",EO2=2.5,"10", EO2=2.75,"11", EO2=3,"12", EO2=3.25,"13", EO2=3.5,"14", EO2=3.75,"15",EO2=4,"16", EO2=-0.25, "17", bq=-0.5, "18")} -> 0 | ER2: 0 | ES2: =IF(ER2=0,"1","2") -> 1 | ET2: {=_xlfn.IFS(ER2=0,"0", ER2=0.25, "1", ER2=0.5,"2", ER2=0.75,"3", ER2=1,"4",ER2=1.25,"5", ER2=1.5,"6", ER2=1.75,"7", ER2=2,"8", ER2=2.25,"9", ER2=2.25,"9",ER2=2.5,"10", ER2=2.75,"11", ER2=3,"12", ER2=3.25,"13", ER2=3.5,"14", ER2=3.75,"15",ER2=4,"16", ER2=-0.25, "17", bq=-0.5, "18")} -> 0 | EU2: 24 | EV2: =VLOOKUP(EU2,LEYENDA!$G$2:$H$8,2,TRUE()) -> 19-24 | EW2: {=_xlfn.IFS(EV2="0-5","1", EV2="6-12","2", EV2="13-18","3", EV2="19-24","4", EV2="25-36","5", EV2="37-48","6", EV2="49-60","7")} -> 4
A3: 1 | B3: 2 | C3: 36344 | E3: =VLOOKUP(A3,'286'!$A$3:$J$600,10,FALSE()) -> ABAD ANOVA, Mª CARMEN | F3: =VLOOKUP(A3,'286'!$A$3:$I$1768,3,FALSE()) -> AACAR | G3: =VLOOKUP(A3,'286'!$A$3:$I$1768,4,FALSE()) -> 25230 | H3: =YEAR(C3)-YEAR(G3) -> 30 | I3: =VLOOKUP(H3,LEYENDA!$C$2:$D$6,2,TRUE()) -> 25-40 | J3: =VLOOKUP(A3,'286'!$A$3:$I$1768,7,FALSE()) -> M | K3: =VLOOKUP(A3,'286'!$A$3:$I$1768,2,FALSE()) -> OD | L3: =VLOOKUP(A3,'286'!$A$3:$I$1768,8,FALSE()) -> D | M3: =VLOOKUP(A3,'286'!$A$3:$I$1768,9,FALSE()) -> D | N3: =IF(R3=O3, "MISMA","CONTRARIA") -> MISMA | O3: {=_xlfn.IFS(L3="D","1", L3="I","2")} -> 1 | P3: {=_xlfn.IFS(K3="OD","1", K3="OI","2")} -> 1 | Q3: {=_xlfn.IFS(J3="M","1", J3="H","2")} -> 1 | R3: {=_xlfn.IFS(M3="D","1", M3="I","2")} -> 1 | S3: {=_xlfn.IFS(N3="CONTRARIA", "1",N3= "MISMA","2")} -> 2 | T3: {=_xlfn.IFS(I3="0-12","1", I3="13-24","2", I3="25-40","3", I3="41-60","4", I3="61-100","5")} -> 3 | U3: 1.5 | V3: =IF(U3="","",IF(AND(U3>=-9,U3<=-6.5),"-9 a -6,5",IF(AND(U3>=-6,U3<=-3.5),"-6 a -3,5",IF(AND(U3>=-3,U3<=-1),"-3 a -1",IF(U3=-0.5,"-0,5",IF(AND(U3>=0,U3<=2.5),"0 a 2,5",IF(AND(U3>=3,U3<=5.5),"3 a 5,5",IF(AND(U3>=6,U3<=8.5),"6 a 8,5",IF(AND(U3>=9,U3<=20),"9 a 20","Fuera de rango"))))))))) -> 0 a 2,5 | W3: =IF(V3="","",IF(V3="-9 a -6,5",2,IF(V3="-6 a -3,5",3,IF(V3="-3 a -1",4,IF(V3="-0,5","NORMA",IF(V3="0 a 2,5",5,IF(V3="3 a 5,5",6,IF(V3="6 a 8,5",7,IF(V3="9 a 20",8,"Fuera de rango"))))))))) -> 5 | X3: 15 | Y3: =IF(X3="","",IF(AND(X3>=0,X3<=4),"0 a 4",IF(AND(X3>=4.5,X3<=8.5),"4,5 a 8,5",IF(X3=9,"9",IF(AND(X3>=9.5,X3<=13),"9,5 a 13",IF(AND(X3>=13.5,X3<=20),"13,5 a 20",IF(AND(X3>=20.5,X3<=35),"20,5 a 35","Fuera de rango"))))))) -> 13,5 a 20 | Z3: =IF(Y3="","",IF(Y3="0 a 4",1,IF(Y3="4,5 a 8,5",2,IF(Y3="9","NORMA",IF(Y3="9,5 a 13",3,IF(Y3="13,5 a 20",4,IF(Y3="20,5 a 35",5,"Fuera de rango"))))))) -> 4 | AA3: 24 | AB3: =IF(AA3="","",IF(AND(AA3>=0,AA3<=9),"0 a 9",IF(AND(AA3>=9.5,AA3<=18.5),"9,5 a 18,5",IF(AA3=19,"19",IF(AND(AA3>=19.5,AA3<=28),"19,5 a 28",IF(AND(AA3>=28.5,AA3<=40),"28,5 a 40","Fuera de rango")))))) -> 19,5 a 28 | AC3: {=_xlfn.IFS(AB3="","",AB3="0 a 9",1,AB3="9,5 a 18,5",2,AB3="19","NORMA",AB3="19,5 a 28",3,AB3="28,5 a 40",4,TRUE(),"Fuera de rango")} -> 3 | AD3: 16 | AE3: =IF(AD3="","",IF(AND(AD3>=-10,AD3<=0),"De -10 a 0",IF(AND(AD3>=0.5,AD3<=9.5),"0,5 a 9,5",IF(AD3=10,"10",IF(AND(AD3>=10.5,AD3<=20),"10,5 a 20",IF(AND(AD3>=20.5,AD3<=40),"20,5 a 40","Fuera de rango")))))) -> 10,5 a 20 | AF3: =IF(AD3="","",IF(AND(AD3>=-10,AD3<=0),1,IF(AND(AD3>=0.5,AD3<=9.5),2,IF(AD3=10,"NORMA",IF(AND(AD3>=10.5,AD3<=20),3,IF(AND(AD3>=20.5,AD3<=40),4,"")))))) -> 3 | AH3: =IF(AG3="","",IF(AND(AG3>=0,AG3<=4),"0 a 4",IF(AND(AG3>=4.5,AG3<=8.5),"4,5 a 8,5",IF(AG3=9,"9",IF(AND(AG3>=9.5,AG3<=13),"9,5 a 13",IF(AND(AG3>=13.5,AG3<=25),"13,5 a 25","Fuera de rango")))))) | AI3: =IF(AH3="","",IF(AH3="0 a 4",1,IF(AH3="4,5 a 8,5",2,IF(AH3="9","NORMA",IF(AH3="9,5 a 13",3,IF(AH3="13,5 a 25",4,"")))))) | AJ3: 3 | AK3: =IF(AJ3="","",IF(AND(AJ3>=-15,AJ3<=-10.5),"-15 a -10,5",IF(AND(AJ3>=-10,AJ3<=-4),"-10 a -4",IF(AND(AJ3>=-4.5,AJ3<=0),"-4,5 a 0",IF(AND(AJ3>=0.5,AJ3<=4.5),"0,5 a 4,5",IF(AJ3=5,"5",IF(AND(AJ3>=5.5,AJ3<=10),"5,5 a 10",IF(AND(AJ3>=10.5,AJ3<=20),"10,5 a 20","Fuera de rango")))))))) -> 0,5 a 4,5 | AL3: =IF(AK3="","",IF(AK3="-15 a -10,5",1,IF(AK3="-10 a -4",2,IF(AK3="-4,5 a 0",3,IF(AK3="0,5 a 4,5",4,IF(AK3="5","NORMA",IF(AK3="5,5 a 10",5,IF(AK3="10,5 a 20",6,"Error")))))))) -> 4 | AM3: 0 | AN3: =IF(AM3="","",IF(AND(AM3>=-7.5,AM3<=-5.5),"-7,5 a -5,5",IF(AND(AM3>=-5,AM3<=-3),"-5 a -3",IF(AND(AM3>=-2.5,AM3<=-0.5),"-2,5 a -0,5",IF(AM3=0,"0,00",IF(AND(AM3>=0.5,AM3<=2.5),"0,5 a 2,5",IF(AND(AM3>=3,AM3<=5),"3 a 5",IF(AND(AM3>=5.5,AM3<=7.5),"5,5 a 7,5",IF(AND(AM3>=8,AM3<=10),"8 a 10","Fuera de rango"))))))))) -> 0,00 | AO3: =IF(AN3="","",IF(AN3="-7,5 a -5,5",1,IF(AN3="-5 a -3",2,IF(AN3="-2,5 a -0,5",3,IF(AN3="0,00","NORMA",IF(AN3="0,5 a 2,5",4,IF(AN3="3 a 5",5,IF(AN3="5,5 a 7,5",6,IF(AN3="8 a 10",7,"Error"))))))))) -> NORMA | AP3: -1.5 | AQ3: =IF(AP3="","",IF(AND(AP3>=-20,AP3<=-9.5),"-20 a -9,5",IF(AND(AP3>=-9,AP3<=-6.5),"-9 a -6,5",IF(AP3=-6,"-6",IF(AND(AP3>=-5.5,AP3<=-3),"-5,5 a -3",IF(AND(AP3>=-2.5,AP3<=0),"-2,5 a 0",IF(AND(AP3>=0.5,AP3<=3),"0,5 a 3",IF(AND(AP3>=3.5,AP3<=6),"3,5 a 6",IF(AND(AP3>=6.5,AP3<=9),"6,5 a 9",IF(AND(AP3>=9.5,AP3<=20),"9,5 a 20","Fuera de rango")))))))))) -> -2,5 a 0 | AR3: =IF(AQ3="","",IF(AQ3="-20 a -9,5",1,IF(AQ3="-9 a -6,5",2,IF(AQ3="-6","NORMA",IF(AQ3="-5,5 a -3",3,IF(AQ3="-2,5 a 0",4,IF(AQ3="0,5 a 3",5,IF(AQ3="3,5 a 6",6,IF(AQ3="6,5 a 9",7,IF(AQ3="9,5 a 20",8,"")))))))))) -> 4 | AS3: 0 | AT3: =IF(AS3="","",IF(AND(AS3>=-16,AS3<=-14),"-16 a -14",IF(AND(AS3>=-13.5,AS3<=-11.5),"-13,5 a -11,5",IF(AND(AS3>=-11,AS3<=-9),"-11 a -9",IF(AND(AS3>=-8.5,AS3<=-6.5),"-8,5 a -6,5",IF(AND(AS3>=-6,AS3<=-4),"-6 a -4",IF(AND(AS3>=-3.5,AS3<=-1.5),"-3,5 a -1,5",IF(AND(AS3>=-1,AS3<=1),"-1 a 1",IF(AND(AS3>=1.5,AS3<=3.5),"1,5 a 3,5",IF(AND(AS3>=4,AS3<=6),"4 a 6",IF(AND(AS3>=6.5,AS3<=8.5),"6,5 a 8,5",IF(AND(AS3>=9,AS3<=11),"9 a 11",IF(AND(AS3>=11.5,AS3<=13.5),"11,5 a 13,5",IF(AND(AS3>=14,AS3<=16),"14 a 16",IF(AND(AS3>=16.5,AS3<=18.5),"16,5 a 18,5",IF(AND(AS3>=19,AS3<=21),"19 a 21","Fuera de rango")))))))))))))))) -> -1 a 1 | AU3: {=IF(AT3="","",_xlfn.IFS(AT3="-16 a -14",1,AT3="-13,5 a -11,5",2,AT3="-11 a -9",3,AT3="-8,5 a -6,5",4,AT3="-6 a -4",5,AT3="-3,5 a -1,5",6,AT3="-1 a 1",7,AT3="1,5 a 3,5",8,AT3="4 a 6","NORMA",AT3="6,5 a 8,5",9,AT3="9 a 11",10,AT3="11,5 a 13,5",11,AT3="14 a 16",12,AT3="16,5 a 18,5",13,AT3="19 a 21",14,TRUE(),""))} -> 7 | AV3: -0.25 | AW3: =IF(AV3="","",IF(AND(AV3>=-1,AV3<=-0.5),"-1 a -0,5",IF(AND(AV3>-0.5,AV3<=0),"De -0,5 a 0",IF(AND(AV3>=0.25,AV3<=0.75),"0,25 a 0,75",IF(AND(AV3>=1,AV3<=1.5),"1 a 1,5",IF(AND(AV3>=1.75,AV3<=2.25),"1,75 a 2,25",IF(AND(AV3>=2.5,AV3<=3),"2,5 a 3",IF(AND(AV3>=3.25,AV3<=3.75),"3,25 a 3,75","Fuera de rango")))))))) -> De -0,5 a 0 | AX3: =IF(AW3="","",IF(OR(AW3="-1 a -0,5",AW3="-1 a -0.5"),1,IF(OR(AW3="De -0,5 a 0",AW3="-0,5 a 0",AW3="De -0.5 a 0"),2,IF(OR(AW3="0,25 a 0,75",AW3="0.25 a 0.75"),"NORMA",IF(OR(AW3="1 a 1,5",AW3="1 a 1.5"),3,IF(OR(AW3="1,75 a 2,25",AW3="1.75 a 2.25"),4,IF(OR(AW3="2,5 a 3",AW3="2.5 a 3"),5,IF(OR(AW3="3,25 a 3,75",AW3="3.25 a 3.75"),6,"")))))))) -> 2 | AY3: -1.5 | AZ3: =IF(AY3="","",IF(AND(AY3>=-20,AY3<=-9.5),"-20 a -9,5",IF(AND(AY3>=-9,AY3<=-6.5),"-9 a -6,5",IF(AY3=-6,"-6",IF(AND(AY3>=-5.5,AY3<=-3),"-5,5 a -3",IF(AND(AY3>=-2.5,AY3<=0),"-2,5 a 0",IF(AND(AY3>=0.5,AY3<=3),"0,5 a 3",IF(AND(AY3>=3.5,AY3<=6),"3,5 a 6","Fuera de rango")))))))) -> -2,5 a 0 | BA3: =IF(AZ3="","",IF(AZ3="-20 a -9,5",1,IF(AZ3="-9 a -6,5",2,IF(AZ3="-6","NORMA",IF(AZ3="-5,5 a -3",3,IF(AZ3="-2,5 a 0",4,IF(AZ3="0,5 a 3",5,IF(AZ3="3,5 a 6",6,"")))))))) -> 4 | BB3: 15 | BC3: {=IF(BB3="","",_xlfn.IFS(AND(BB3>=0,BB3<=2),"0 a 2",AND(BB3>=2.5,BB3<=4.5),"2,5 a 4,5",AND(BB3>=5,BB3<=7),"5 a 7",AND(BB3>=7.5,BB3<=9.5),"7,5 a 9,5",AND(BB3>=10,BB3<=12),"10 a 12",AND(BB3>=12.5,BB3<=14.5),"12,5 a 14,5",BB3=15,"15",AND(BB3>=15.5,BB3<=17.5),"15,5 a 17,5",AND(BB3>=18,BB3<=20),"18 a 20",AND(BB3>=20.5,BB3<=22.5),"20,5 a 22,5",AND(BB3>=23,BB3<=25),"23 a 25",TRUE(),"Fuera de rango"))} -> 15 | BD3: {=IF(BC3="","",_xlfn.IFS(BC3="0 a 2",1,BC3="2,5 a 4,5",2,BC3="5 a 7",3,BC3="7,5 a 9,5",4,BC3="10 a 12",5,BC3="12,5 a 14,5",6,BC3="15","NORMA",BC3="15,5 a 17,5",7,BC3="18 a 20",8,BC3="20,5 a 22,5",9,BC3="23 a 25",10,TRUE(),"Fuera de rango"))} -> NORMA | BE3: 21 | BF3: =IF(BE3="","",IF(AND(BE3>=-20,BE3<=-10),"-20 a -10",IF(AND(BE3>=-9.5,BE3<=0.5),"-9,5 a 0,5",IF(AND(BE3>=1,BE3<=11),"1 a 11",IF(AND(BE3>=11.5,BE3<=20.5),"11,5 a 20,5",IF(BE3=21,"21",IF(AND(BE3>=21.5,BE3<=31.5),"21,5 a 31,5",IF(AND(BE3>=32,BE3<=42),"32 a 42","Fuera de rango")))))))) -> 21 | BG3: =IF(BF3="","",IF(BF3="-20 a -10",1,IF(BF3="-9,5 a 0,5",2,IF(BF3="1 a 11",3,IF(BF3="11,5 a 20,5",4,IF(BF3="21","NORMA",IF(BF3="21,5 a 31,5",5,IF(BF3="32 a 42",6,"")))))))) -> NORMA | BH3: 12 | BI3: =IF(BH3="","",IF(AND(BH3>=-20,BH3<=-15),"-20 a -15",IF(AND(BH3>=-14.5,BH3<=-9.5),"-14,5 a -9,5",IF(AND(BH3>=-9,BH3<=-4),"-9 a -4",IF(AND(BH3>=-3.5,BH3<=2.5),"-3,5 a 2,5",IF(AND(BH3>=3,BH3<=8),"3 a 8",IF(AND(BH3>=8.5,BH3<=14.5),"8,5 a 14,5",IF(BH3=15,"15",IF(AND(BH3>=15.5,BH3<=20.5),"15,5 a 20,5",IF(AND(BH3>=21,BH3<=26),"21 a 26","Fuera de rango")))))))))) -> 8,5 a 14,5 | BJ3: =IF(BI3="","",IF(BI3="-20 a -15",1,IF(BI3="-14,5 a -9,5",2,IF(BI3="-9 a -4",3,IF(BI3="-3,5 a 2,5",4,IF(BI3="3 a 8",5,IF(BI3="8,5 a 14,5",6,IF(BI3="15","NORMA",IF(BI3="15,5 a 20,5",7,IF(BI3="21 a 26",8,IF(BI3="26,5 a 31,5",9,""))))))))))) -> 6 | BK3: 12 | BL3: =IF(BK3="","",IF(AND(BK3>=0,BK3<=2),"0 - 2",IF(AND(BK3>=2.5,BK3<=4.5),"2,5 - 4,5",IF(AND(BK3>=5,BK3<=7),"5 - 7",IF(AND(BK3>=7.5,BK3<=9.5),"7,5 - 9,5",IF(AND(BK3>=10,BK3<=12),"10 - 12",IF(AND(BK3>=12.5,BK3<=13.5),"12,5 - 13,5",IF(BK3=14,"14",IF(AND(BK3>=14.5,BK3<=16.5),"14,5 - 16,5",IF(AND(BK3>=17,BK3<=19),"17 - 19",IF(AND(BK3>=19.5,BK3<=21.5),"19,5 - 21,5",IF(AND(BK3>=22,BK3<=24),"22 - 24",IF(AND(BK3>=24.5,BK3<=26.5),"24,5 - 26,5",IF(AND(BK3>=27,BK3<=29),"27 - 29",IF(AND(BK3>=29.5,BK3<=30),"29,5 - 30","Fuera de rango"))))))))))))))) -> 10 - 12 | BM3: =IF(BL3="","",IF(BL3="0 - 2",1,IF(BL3="2,5 - 4,5",2,IF(BL3="5 - 7",3,IF(BL3="7,5 - 9,5",4,IF(BL3="10 - 12",5,IF(BL3="12,5 - 13,5",6,IF(BL3="14","NORMA",IF(BL3="14,5 - 16,5",7,IF(BL3="17 - 19",8,IF(BL3="19,5 - 21,5",9,IF(BL3="22 - 24",10,IF(BL3="24,5 - 26,5",11,IF(BL3="27 - 29",12,IF(BL3="29,5 - 30",13,""))))))))))))))) -> 5 | BN3: 16 | BO3: =IF(BN3="","",IF(AND(BN3>=-20,BN3<=-10),"-20 a -10",IF(AND(BN3>=-9.5,BN3<=0.5),"-9,5 a 0,5",IF(AND(BN3>=1,BN3<=11),"1 a 11",IF(AND(BN3>=11.5,BN3<=21.5),"11,5 a 21,5",IF(BN3=22,"22",IF(AND(BN3>=22.5,BN3<=32.5),"22,5 a 32,5",IF(AND(BN3>=33,BN3<=43),"33 a 43","Fuera de rango")))))))) -> 11,5 a 21,5 | BP3: =IF(BO3="","",IF(BO3="-20 a -10",1,IF(BO3="-9,5 a 0,5",2,IF(BO3="1 a 11",3,IF(BO3="11,5 a 21,5",4,IF(BO3="22","NORMA",IF(BO3="22,5 a 32,5",5,IF(BO3="33 a 43",6,"")))))))) -> 4 | BQ3: 6 | BR3: =IF(BQ3="","",IF(AND(BQ3>=-20,BQ3<=-15),"-20 a -15",IF(AND(BQ3>=-14.5,BQ3<=-9.5),"-14,5 a -9,5",IF(AND(BQ3>=-9,BQ3<=-4),"-9 a -4",IF(AND(BQ3>=-3.5,BQ3<=2.5),"-3,5 a 2,5",IF(AND(BQ3>=3,BQ3<=8),"3 a 8",IF(AND(BQ3>=8.5,BQ3<=13.5),"8,5 a 13,5",IF(AND(BQ3>=14,BQ3<=17.5),"14 a 17,5",IF(BQ3=18,"18",IF(AND(BQ3>=18.5,BQ3<=23.5),"18,5 a 23,5",IF(AND(BQ3>=24,BQ3<=29),"24 a 29",IF(AND(BQ3>=29.5,BQ3<=34.5),"29,5 a 34,5",IF(AND(BQ3>=35,BQ3<=40),"35 a 40","Fuera de rango"))))))))))))) -> 3 a 8 | BS3: =IF(BR3="","",IF(BR3="-20 a -15",1,IF(BR3="-14,5 a -9,5",2,IF(BR3="-9 a -4",3,IF(BR3="-3,5 a 2,5",4,IF(BR3="3 a 8",5,IF(BR3="8,5 a 13,5",6,IF(BR3="14 a 17,5",7,IF(BR3="18","NORMA",IF(BR3="18,5 a 23,5",8,IF(BR3="24 a 29",9,IF(BR3="29,5 a 34,5",10,IF(BR3="35 a 40",11,""))))))))))))) -> 5 | BT3: -0.5 | BU3: =IF(BT3="","",IF(AND(BT3>=-20,BT3<=-18),"-20 a -18",IF(AND(BT3>=-17.5,BT3<=-15.5),"-17,5 a -15,5",IF(AND(BT3>=-15,BT3<=-13),"-15 a -13",IF(AND(BT3>=-12.5,BT3<=-10.5),"-12,5 a -10,5",IF(AND(BT3>=-10,BT3<=-8),"-10 a -8",IF(AND(BT3>=-7.5,BT3<=-5.5),"-7,5 a -5,5",IF(AND(BT3>=-5,BT3<=-3),"-5 a -3",IF(AND(BT3>=-2.5,BT3<=-0.5),"-2,5 a -0,5",IF(BT3=0,"0",IF(AND(BT3>=0.5,BT3<=2.5),"0,5 a 2,5",IF(AND(BT3>=3,BT3<=5),"3 a 5",IF(AND(BT3>=5.5,BT3<=7.5),"5,5 a 7,5",IF(AND(BT3>=8,BT3<=10),"8 a 10",IF(AND(BT3>=10.5,BT3<=12.5),"10,5 a 12,5",IF(AND(BT3>=13,BT3<=15),"13 a 15",IF(AND(BT3>=15.5,BT3<=17.5),"15,5 a 17,5",IF(AND(BT3>=18,BT3<=20),"18 a 20","Fuera de rango")))))))))))))))))) -> -2,5 a -0,5 | BV3: =IF(BT3="","",IF(BT3=0,"NORMA",IF(AND(BT3>=-20,BT3<=-18),2,IF(AND(BT3>=-17.5,BT3<=-15.5),2,IF(AND(BT3>=-15,BT3<=-13),3,IF(AND(BT3>=-12.5,BT3<=-10.5),4,IF(AND(BT3>=-10,BT3<=-8),5,IF(AND(BT3>=-7.5,BT3<=-5.5),6,IF(AND(BT3>=-5,BT3<=-3),7,IF(AND(BT3>=-2.5,BT3<=-0.5),8,IF(AND(BT3>=0.5,BT3<=2.5),9,IF(AND(BT3>=3,BT3<=5),10,IF(AND(BT3>=5.5,BT3<=7.5),11,IF(AND(BT3>=8,BT3<=10),12,IF(AND(BT3>=10.5,BT3<=12.5),13,IF(AND(BT3>=13,BT3<=15),14,IF(AND(BT3>=15.5,BT3<=17.5),15,IF(AND(BT3>=18,BT3<=20),16,"Fuera de rango")))))))))))))))))) -> 8 | BW3: -4.5 | BX3: =18.5- (0.3*H3) -> 9.5 | BY3: =(BW3)-(BX3) -> -14 | BZ3: =IF(BY3="","",IF(BY3<-27.5,"De -30 a -28",IF(BY3<-25,"De -27,5 a -25,5",IF(BY3<-22.5,"De -25 a -23",IF(BY3<-20,"De -22,5 a -20,5",IF(BY3<-17.5,"De -20 a -18",IF(BY3<-15,"De -17,5 a -15,5",IF(BY3<-12.5,"De -15 a -13",IF(BY3<-10,"De -12,5 a -10,5",IF(BY3<-7.5,"De -10 a -8",IF(BY3<-5,"De -7,5 a -5,5",IF(BY3<-2.5,"De -5 a -3",IF(BY3<0,"De -2,5 a -0,5",IF(BY3<2.5,"De 0 a 2",IF(BY3<5,"De 2,5 a 4,5",IF(BY3<7.5,"De 5 a 7",IF(BY3<10,"De 7,5 a 9,5",IF(BY3<12.5,"De 10 a 12",IF(BY3<15,"De 12,5 a 14,5",IF(BY3<17.5,"De 15 a 17",IF(BY3<20,"De 17,5 a 19,5",IF(BY3<22.5,"De 20 a 22",IF(BY3<25,"De 22,5 a 24,5",IF(BY3<27.5,"De 25 a 27","De 27,5 a 30")))))))))))))))))))))))) -> De -15 a -13 | CA3: =IF(BY3="","",IF(BY3<=-28,1,IF(BY3<=-25.5,2,IF(BY3<=-23,3,IF(BY3<=-20.5,4,IF(BY3<=-18,5,IF(BY3<=-15.5,6,IF(BY3<=-13,7,IF(BY3<=-10.5,8,IF(BY3<=-8,9,IF(BY3<=-5.5,10,IF(BY3<=-3,11,IF(BY3<=-0.5,12,IF(BY3<=2,13,IF(BY3<=4.5,14,IF(BY3<=7,15,IF(BY3<=9.5,16,IF(BY3<=12,17,IF(BY3<=14.5,18,IF(BY3<=17,19,IF(BY3<=19.5,20,IF(BY3<=22,21,IF(BY3<=24.5,22,IF(BY3<=27,23,IF(BY3<=30,24,"Fuera de rango"))))))))))))))))))))))))) -> 7 | CB3: -4.5 | CC3: =18.5- (0.3*H3) -> 9.5 | CD3: =(CB3)-(CC3) -> -14 | CE3: =IF(CD3="","",IF(CD3<-27.5,"De -30 a -28",IF(CD3<-25,"De -27,5 a -25,5",IF(CD3<-22.5,"De -25 a -23",IF(CD3<-20,"De -22,5 a -20,5",IF(CD3<-17.5,"De -20 a -18",IF(CD3<-15,"De -17,5 a -15,5",IF(CD3<-12.5,"De -15 a -13",IF(CD3<-10,"De -12,5 a -10,5",IF(CD3<-7.5,"De -10 a -8",IF(CD3<-5,"De -7,5 a -5,5",IF(CD3<-2.5,"De -5 a -3",IF(CD3<0,"De -2,5 a -0,5",IF(CD3<=2,"De 0 a 2",IF(CD3<=4.5,"De 2,5 a 4,5",IF(CD3<=7,"De 5 a 7",IF(CD3<=9.5,"De 7,5 a 9,5",IF(CD3<=12,"De 10 a 12",IF(CD3<=14.5,"De 12,5 a 14,5",IF(CD3<=17,"De 15 a 17",IF(CD3<=19.5,"De 17,5 a 19,5",IF(CD3<=22,"De 20 a 22",IF(CD3<=24.5,"De 22,5 a 24,5",IF(CD3<=27,"De 25 a 27","De 27,5 a 30")))))))))))))))))))))))) -> De -15 a -13 | CF3: =IF(CD3="","",IF(CD3<-27.5,1,IF(CD3<-25,2,IF(CD3<-22.5,3,IF(CD3<-20,4,IF(CD3<-17.5,5,IF(CD3<-15,6,IF(CD3<-12.5,7,IF(CD3<-10,8,IF(CD3<-7.5,9,IF(CD3<-5,10,IF(CD3<-2.5,11,IF(CD3<0,12,IF(CD3<2.5,13,IF(CD3<5,14,IF(CD3<7.5,15,IF(CD3<10,16,IF(CD3<12.5,17,IF(CD3<15,18,IF(CD3<17.5,19,IF(CD3<20,20,IF(CD3<22.5,21,IF(CD3<25,22,IF(CD3<27.5,23,24)))))))))))))))))))))))) -> 7 | CG3: -2.75 | CH3: =IF(CG3="","",IF(AND(CG3>=-10,CG3<=-9.5),"-10 a -9,5",IF(AND(CG3>-9.5,CG3<=-8.5),"-9 a -8,5",IF(AND(CG3>-8.5,CG3<=-7.5),"-8 a -7,5",IF(AND(CG3>-7.5,CG3<=-6.5),"-7 a -6,5",IF(AND(CG3>-6.5,CG3<=-5.5),"-6 a -5,5",IF(AND(CG3>-5.5,CG3<=-4.5),"-5 a -4,5",IF(AND(CG3>-4.5,CG3<=-3.5),"-4 a -3,5",IF(AND(CG3>-3.5,CG3<=-2.5),"-3 a -2,5",IF(CG3=-2.25,"-2,25",IF(AND(CG3>-2.5,CG3<=-1.5),"-2 a -1,5",IF(AND(CG3>-1.5,CG3<=-0.5),"-1 a -0,5",IF(AND(CG3>-0.5,CG3<=0.5),"0 a 0,5",IF(AND(CG3>0.5,CG3<=1.5),"1 a 1,5",IF(AND(CG3>1.5,CG3<=2.5),"2 a 2,5",IF(AND(CG3>2.5,CG3<=3.5),"3 a 3,5",IF(AND(CG3>3.5,CG3<=4.5),"4 a 4,5",IF(AND(CG3>4.5,CG3<=5.5),"5 a 5,5",IF(AND(CG3>5.5,CG3<=6.5),"6 a 6,5",IF(AND(CG3>6.5,CG3<=7.5),"7 a 7,5",IF(AND(CG3>7.5,CG3<=8.5),"8 a 8,5",IF(AND(CG3>8.5,CG3<=9.5),"9 a 9,5",IF(CG3>=10,"10","Fuera de rango"))))))))))))))))))))))) -> -3 a -2,5 | CI3: =IF(CG3="","",IF(CG3=-2.25,"NORMA",IF(CG3<=-9.5,1,IF(CG3<=-8.5,2,IF(CG3<=-7.5,3,IF(CG3<=-6.5,4,IF(CG3<=-5.5,5,IF(CG3<=-4.5,6,IF(CG3<=-3.5,7,IF(CG3<=-2.5,8,IF(CG3<=-1.5,9,IF(CG3<=-0.5,10,IF(CG3<=0.5,11,IF(CG3<=1.5,12,IF(CG3<=2.5,13,IF(CG3<=3.5,14,IF(CG3<=4.5,15,IF(CG3<=5.5,16,IF(CG3<=6.5,17,IF(CG3<=7.5,18,IF(CG3<=8.5,19,IF(CG3<=9.5,20,IF(CG3=10,21,"Fuera de rango"))))))))))))))))))))))) -> 8 | CJ3: 2 | CK3: =IF(CJ3="","",IF(AND(CJ3>=-6,CJ3<=-5.5),"-6 a -5,5",IF(AND(CJ3>-5.5,CJ3<=-4.5),"-5 a -4,5",IF(AND(CJ3>-4.5,CJ3<=-3.5),"-4 a -3,5",IF(AND(CJ3>-3.5,CJ3<=-2.5),"-3 a -2,5",IF(AND(CJ3>-2.5,CJ3<=-1.5),"-2 a -1,5",IF(AND(CJ3>-1.5,CJ3<=-0.5),"-1 a -0,5",IF(AND(CJ3>-0.5,CJ3<=0.5),"0 a 0,5",IF(AND(CJ3>0.5,CJ3<=1.5),"1 a 1,5",IF(AND(CJ3>1.5,CJ3<2.5),"2",IF(AND(CJ3>=2.5,CJ3<=3),"2,5 a 3",IF(AND(CJ3>3,CJ3<=4),"3,5 a 4",IF(AND(CJ3>4,CJ3<=5),"4,5 a 5",IF(AND(CJ3>5,CJ3<=6),"5,5 a 6",IF(AND(CJ3>6,CJ3<=7),"6,5 a 7",IF(AND(CJ3>7,CJ3<=8),"7,5 a 8",IF(AND(CJ3>8,CJ3<=9.5),"8,5 a 9,5",IF(CJ3=10,"10","Fuera de rango")))))))))))))))))) -> 2 | CL3: =IF(CK3="","",IF(OR(CK3="-6 a -5,5",CK3="-6 - -5,5"),1,IF(OR(CK3="-5 a -4,5",CK3="-5 - -4,5"),2,IF(OR(CK3="-4 a -3,5",CK3="-4 - -3,5"),3,IF(OR(CK3="-3 a -2,5",CK3="-3 - -2,5"),4,IF(OR(CK3="-2 a -1,5",CK3="-2 - -1,5"),5,IF(OR(CK3="-1 a -0,5",CK3="-1 - -0,5"),6,IF(OR(CK3="0 a 0,5",CK3="0 - 0,5"),7,IF(OR(CK3="1 a 1,5",CK3="1 - 1,5"),8,IF(CK3="2","NORMA",IF(OR(CK3="2,5 a 3",CK3="2,5 - 3"),9,IF(OR(CK3="3,5 a 4",CK3="3,5 - 4"),10,IF(OR(CK3="4,5 a 5",CK3="4,5 - 5"),11,IF(OR(CK3="5,5 a 6",CK3="5,5 - 6"),12,IF(OR(CK3="6,5 a 7",CK3="6,5 - 7"),13,IF(OR(CK3="7,5 a 8",CK3="7,5 - 8"),14,IF(OR(CK3="8,5 a 9",CK3="8,5 - 9,5",CK3="9 a 9,5"),15,IF(CK3="10",15,IF(OR(CK3="0,5 a 1",CK3="0,5 - 1"),7,"Fuera de rango"))))))))))))))))))) -> NORMA | CM3: 0 | CN3: =IF(CM3=0,"0", " ") -> 0 | CO3: =IF(CM3>0,"EME"," ") | CP3: 0 | CQ3: =IF(CP3>0,"0", " ") | CR3: =IF(CP3>0,"EME"," ") | CS3: 0 | CT3: =IF(CS3>0,"1", " ") | CU3: =IF(CS3>0,"HIP"," ") | CV3: 0 | CW3: =IF(CV3>0,"1", " ") | CX3: =IF(CV3>0,"HIP"," ") | CY3: -1.5 | CZ3: =IF(CY3<0,"2"," ") -> 2 | DA3: =IF(CY3<0,"MIO"," ") -> MIO | DB3: -2 | DC3: =IF(DB3<0,"2"," ") -> 2 | DD3: =IF(DB3<0,"MIO"," ") -> MIO | DE3: -0.25 | DF3: =IF(DE3<0,"3"," ") -> 3 | DG3: =IF(DE3<0,"AST"," ") -> AST | DH3: -0.75 | DI3: =IF(DH3<0,"3"," ") -> 3 | DJ3: =IF(DH3<0,"AST"," ") -> AST | DK3: 0 | DL3: =IF(DK3>0,"4"," ") | DM3: =IF(DK3>0,"PRE"," ") | DN3: 0 | DO3: =IF(DN3>0,"4"," ") | DP3: =IF(DN3>0,"PRE"," ") | DQ3: 2 | DR3: 2 | DS3: =CONCATENATE(CO3,CU3,DA3,DG3,DM3) -> MIOAST | DT3: {=_xlfn.IFS(DS3="EME ","0", DS3=" HIP ","1", DS3=" MIO ","2", DS3=" AST ","3", DS3=" PRE","4", DS3="EME PRE","5", DS3=" HIP PRE","6", DS3=" HIP AST ","7", DS3=" MIO PRE","8", DS3=" MIOAST ","9", DS3=" ASTPRE","10",DS3=" HIP ASTPRE","11", DS3=" MIOASTPRE","12", DS3=" ","0")} -> 9 | DU3: NO | DV3: {=_xlfn.IFS(DU3="SI","2", DU3="NO","1")} -> 1 | DW3: 0 | DX3: =IF(DW3=0,"1","2") -> 1 | DY3: {=_xlfn.IFS(DW3=0,"0", DW3=0.25, "1", DW3=0.5,"2", DW3=0.75,"3", DW3=1,"4",DW3=1.25,"5", DW3=1.5,"6", DW3=1.75,"7", DW3=2,"8")} -> 0 | DZ3: 0 | EA3: =IF(DZ3=0,"1","2") -> 1 | EB3: {=_xlfn.IFS(DZ3=0,"0", DZ3=0.25, "1", DZ3=0.5,"2", DZ3=0.75,"3", DZ3=1,"4",DZ3=1.25,"5", DZ3=1.5,"6", DZ3=1.75,"7", DZ3=2,"8")} -> 0 | EC3: -0.25 | ED3: =IF(EC3=0,"1","2") -> 2 | EE3: {=_xlfn.IFS(EC3=0,"0", EC3=-0.25, "1", EC3=-0.5,"2", EC3=-0.75,"3", EC3=-1,"4",EC3=-1.25,"5", EC3=-1.5,"6", EC3=-1.75,"7", EC3=-2,"8", EC3=-2.25,"9",EC3=-2.5,"10", EC3=-2.75,"11", EC3=-3,"12", EC3=-3.25,"13", EC3=-3.5,"14", EC3=-3.75,"15",EC3=-4,"16")} -> 1 | EF3: -0.25 | EG3: =IF(EF3=0,"1","2") -> 2 | EH3: {=_xlfn.IFS(EF3=0,"0", EF3=-0.25, "1", EF3=-0.5,"2", EF3=-0.75,"3", EF3=-1,"4",EF3=-1.25,"5", EF3=-1.5,"6", EF3=-1.75,"7", EF3=-2,"8", EF3=-2.25,"9",EF3=-2.5,"10", EF3=-2.75,"11", EF3=-3,"12", EF3=-3.25,"13", EF3=-3.5,"14", EF3=-3.75,"15",EF3=-4,"16")} -> 1 | EI3: 0 | EJ3: =IF(EI3=0,"1","2") -> 1 | EK3: {=_xlfn.IFS(EI3=0,"0", EI3=-0.25, "1", EI3=-0.5,"2", EI3=-0.75,"3", EI3=-1,"4",EI3=-1.25,"5", EI3=-1.5,"6", EI3=-1.75,"7", EI3=-2,"8", EI3=-2.25,"9", EI3=-2.25,"9",EI3=-2.5,"10", EI3=-2.75,"11", EI3=-3,"12", EI3=-3.25,"13", EI3=-3.5,"14", EI3=-3.75,"15",EI3=-4,"16", EI3=0.25, "17", EI3=0.5, "18")} -> 0 | EL3: -0.25 | EM3: =IF(EL3=0,"1","2") -> 2 | EN3: {=_xlfn.IFS(EL3=0.25,"17",EL3=0.5,"18", EL3=0,"0", EL3=-0.25, "1", EL3=-0.5,"2", EL3=-0.75,"3", EL3=-1,"4",EL3=-1.25,"5", EL3=-1.5,"6", EL3=-1.75,"7", EL3=-2,"8",EL3= -2.25,"9",EL3=-2.5,"10",EL3= -2.75,"11",EL3= -3,"12",EL3= -3.25,"13",EL3= -3.5,"14",EL3= -3.75,"15",EL3=-4,"16")} -> 1 | EO3: 0 | EP3: =IF(EO3=0,"1","2") -> 1 | EQ3: {=_xlfn.IFS(EO3=0,"0", EO3=0.25, "1", EO3=0.5,"2", EO3=0.75,"3", EO3=1,"4",EO3=1.25,"5", EO3=1.5,"6", EO3=1.75,"7", EO3=2,"8", EO3=2.25,"9", EO3=2.25,"9",EO3=2.5,"10", EO3=2.75,"11", EO3=3,"12", EO3=3.25,"13", EO3=3.5,"14", EO3=3.75,"15",EO3=4,"16", EO3=-0.25, "17", bq=-0.5, "18")} -> 0 | ER3: 0 | ES3: =IF(ER3=0,"1","2") -> 1 | ET3: {=_xlfn.IFS(ER3=0,"0", ER3=0.25, "1", ER3=0.5,"2", ER3=0.75,"3", ER3=1,"4",ER3=1.25,"5", ER3=1.5,"6", ER3=1.75,"7", ER3=2,"8", ER3=2.25,"9", ER3=2.25,"9",ER3=2.5,"10", ER3=2.75,"11", ER3=3,"12", ER3=3.25,"13", ER3=3.5,"14", ER3=3.75,"15",ER3=4,"16", ER3=-0.25, "17", bq=-0.5, "18")} -> 0 | EU3: 8 | EV3: =VLOOKUP(EU3,LEYENDA!$G$2:$H$8,2,TRUE()) -> 6-12 | EW3: {=_xlfn.IFS(EV3="0-5","1", EV3="6-12","2", EV3="13-18","3", EV3="19-24","4", EV3="25-36","5", EV3="37-48","6", EV3="49-60","7")} -> 2
